<?xml version="1.0" encoding="utf-8"?>
<!-- This URDF was automatically created by SolidWorks to URDF Exporter! Originally created by Stephen Brawner (brawner@gmail.com) 
     Commit Version: 1.6.0-4-g7f85cfe  Build Version: 1.6.7995.38578
     For more information, please see http://wiki.ros.org/sw_urdf_exporter -->
<robot
  name="RoboticARMurdf">
  <link
    name="base_link">
    <inertial>
      <origin
        xyz="5.11583882566863E-06 -4.970201199897E-06 0.0292081671543987"
        rpy="0 0 0" />
      <mass
        value="1.12635106638512" />
      <inertia
        ixx="0.00203037848776675"
        ixy="3.18650414985995E-07"
        ixz="-1.32343768470137E-07"
        iyy="0.00203038057182127"
        iyz="1.28842828252533E-07"
        izz="0.0033785920550505" />
    </inertial>
    <visual>
      <origin
        xyz="0 0 0"
        rpy="0 0 0" />
      <geometry>
        <mesh
          filename="package://RoboticARMurdf/meshes/base_link.STL" />
      </geometry>
      <material
        name="">
        <color
          rgba="0.219607843137255 0.219607843137255 0.219607843137255 1" />
      </material>
    </visual>
    <collision>
      <origin
        xyz="0 0 0"
        rpy="0 0 0" />
      <geometry>
        <mesh
          filename="package://RoboticARMurdf/meshes/base_link.STL" />
      </geometry>
    </collision>
  </link>
  <link
    name="link_2">
    <inertial>
      <origin
        xyz="-0.021818 0.089587 0.23306"
        rpy="0 0 0" />
      <mass
        value="0.26927" />
      <inertia
        ixx="0.0004027"
        ixy="9.1655E-05"
        ixz="0.00011621"
        iyy="0.00039751"
        iyz="-0.00011933"
        izz="0.00036148" />
    </inertial>
    <visual>
      <origin
        xyz="0 0 0"
        rpy="0 0 0" />
      <geometry>
        <mesh
          filename="package://RoboticARMurdf/meshes/link_2.STL" />
      </geometry>
      <material
        name="">
        <color
          rgba="0.79216 0.81961 0.93333 1" />
      </material>
    </visual>
    <collision>
      <origin
        xyz="0 0 0"
        rpy="0 0 0" />
      <geometry>
        <mesh
          filename="package://RoboticARMurdf/meshes/link_2.STL" />
      </geometry>
    </collision>
  </link>
  <joint
    name="joint_1"
    type="continuous">
    <origin
      xyz="0.0465036846489575 0.0661492646377312 -0.148773986749193"
      rpy="0 0 2.37519579033159" />
    <parent
      link="base_link" />
    <child
      link="link_2" />
    <axis
      xyz="0 0 -1" />
  </joint>
  <link
    name="link_3">
    <inertial>
      <origin
        xyz="0.008459 0.016618 0.070811"
        rpy="0 0 0" />
      <mass
        value="0.11268" />
      <inertia
        ixx="0.00053374"
        ixy="7.9433E-06"
        ixz="4.3403E-05"
        iyy="0.00053259"
        iyz="-4.238E-05"
        izz="2.3623E-05" />
    </inertial>
    <visual>
      <origin
        xyz="0 0 0"
        rpy="0 0 0" />
      <geometry>
        <mesh
          filename="package://RoboticARMurdf/meshes/link_3.STL" />
      </geometry>
      <material
        name="">
        <color
          rgba="0.65882 0.61961 0.56078 1" />
      </material>
    </visual>
    <collision>
      <origin
        xyz="0 0 0"
        rpy="0 0 0" />
      <geometry>
        <mesh
          filename="package://RoboticARMurdf/meshes/link_3.STL" />
      </geometry>
    </collision>
  </link>
  <joint
    name="joint_2"
    type="continuous">
    <origin
      xyz="-0.059089 0.12843 0.28093"
      rpy="0 0 0" />
    <parent
      link="link_2" />
    <child
      link="link_3" />
    <axis
      xyz="-0.72041 -0.69354 0" />
  </joint>
  <link
    name="link_4">
    <inertial>
      <origin
        xyz="-0.02369 0.0035803 -0.010272"
        rpy="0 0 0" />
      <mass
        value="0.19257" />
      <inertia
        ixx="0.00028196"
        ixy="1.8497E-05"
        ixz="-4.4468E-05"
        iyy="0.00029693"
        iyz="4.3819E-05"
        izz="8.886E-05" />
    </inertial>
    <visual>
      <origin
        xyz="0 0 0"
        rpy="0 0 0" />
      <geometry>
        <mesh
          filename="package://RoboticARMurdf/meshes/link_4.STL" />
      </geometry>
      <material
        name="">
        <color
          rgba="0.68627 0.65882 0.63922 1" />
      </material>
    </visual>
    <collision>
      <origin
        xyz="0 0 0"
        rpy="0 0 0" />
      <geometry>
        <mesh
          filename="package://RoboticARMurdf/meshes/link_4.STL" />
      </geometry>
    </collision>
  </link>
  <joint
    name="joint_3"
    type="continuous">
    <origin
      xyz="-0.017076 0.017738 0.17326"
      rpy="0 0 0" />
    <parent
      link="link_3" />
    <child
      link="link_4" />
    <axis
      xyz="0.72041 0.69354 0" />
  </joint>
  <link
    name="link_5">
    <inertial>
      <origin
        xyz="-0.0073748 0.0076605 -0.051308"
        rpy="0 0 0" />
      <mass
        value="0.077165" />
      <inertia
        ixx="4.5776E-05"
        ixy="2.65E-07"
        ixz="-4.8731E-06"
        iyy="4.7054E-05"
        iyz="5.2887E-06"
        izz="1.8289E-05" />
    </inertial>
    <visual>
      <origin
        xyz="0 0 0"
        rpy="0 0 0" />
      <geometry>
        <mesh
          filename="package://RoboticARMurdf/meshes/link_5.STL" />
      </geometry>
      <material
        name="">
        <color
          rgba="0 0 0 1" />
      </material>
    </visual>
    <collision>
      <origin
        xyz="0 0 0"
        rpy="0 0 0" />
      <geometry>
        <mesh
          filename="package://RoboticARMurdf/meshes/link_5.STL" />
      </geometry>
    </collision>
  </link>
  <joint
    name="joint_4"
    type="continuous">
    <origin
      xyz="-0.04454 0.023486 -0.10162"
      rpy="0 0 0" />
    <parent
      link="link_4" />
    <child
      link="link_5" />
    <axis
      xyz="0.16354 -0.16988 0.9718" />
  </joint>
  <link
    name="link_6">
    <inertial>
      <origin
        xyz="0.0025989 -0.011366 -0.026325"
        rpy="0 0 0" />
      <mass
        value="0.031582" />
      <inertia
        ixx="6.6023E-06"
        ixy="2.6238E-08"
        ixz="-2.3005E-08"
        iyy="6.3891E-06"
        iyz="-3.5664E-07"
        izz="5.6473E-06" />
    </inertial>
    <visual>
      <origin
        xyz="0 0 0"
        rpy="0 0 0" />
      <geometry>
        <mesh
          filename="package://RoboticARMurdf/meshes/link_6.STL" />
      </geometry>
      <material
        name="">
        <color
          rgba="1 1 1 1" />
      </material>
    </visual>
    <collision>
      <origin
        xyz="0 0 0"
        rpy="0 0 0" />
      <geometry>
        <mesh
          filename="package://RoboticARMurdf/meshes/link_6.STL" />
      </geometry>
    </collision>
  </link>
  <joint
    name="joint_5"
    type="continuous">
    <origin
      xyz="-0.012344 0.012822 -0.073347"
      rpy="0 0 0" />
    <parent
      link="link_5" />
    <child
      link="link_6" />
    <axis
      xyz="0.92813 0.36041 -0.093192" />
  </joint>
  <link
    name="gripper arm">
    <inertial>
      <origin
        xyz="0.0021424 -0.008207 -0.017888"
        rpy="0 0 0" />
      <mass
        value="0.0091291" />
      <inertia
        ixx="1.0322E-06"
        ixy="9.5437E-10"
        ixz="-9.1231E-09"
        iyy="1.0232E-06"
        iyz="7.4993E-08"
        izz="1.1928E-06" />
    </inertial>
    <visual>
      <origin
        xyz="0 0 0"
        rpy="0 0 0" />
      <geometry>
        <mesh
          filename="package://RoboticARMurdf/meshes/gripper arm.STL" />
      </geometry>
      <material
        name="">
        <color
          rgba="0.8 0.80784 0.8 1" />
      </material>
    </visual>
    <collision>
      <origin
        xyz="0 0 0"
        rpy="0 0 0" />
      <geometry>
        <mesh
          filename="package://RoboticARMurdf/meshes/gripper arm.STL" />
      </geometry>
    </collision>
  </link>
  <joint
    name="joint_6"
    type="continuous">
    <origin
      xyz="0.0013458 -0.010986 -0.029085"
      rpy="0 0 0" />
    <parent
      link="link_6" />
    <child
      link="gripper arm" />
    <axis
      xyz="-0.043245 0.35303 0.93461" />
  </joint>
</robot>